Workbook

Sheet OPERATIONS BRAIN
A1: OPERATIONS HEALTH
A2: =TODAY() -> 46109
A4: ESTADO DE PROYECTOS
A6: Activos | C6: =COUNTIF('Estado de Proyectos'!I:I,"🔄 En proceso") -> 0
A7: Completados | C7: =COUNTIF('Estado de Proyectos'!I:I,"✅ Completado") -> 58
A8: Pausados | C8: =COUNTIF('Estado de Proyectos'!I:I,"⏸️ Sin iniciar") -> 0
A11: EFICIECIA
A12: Tiempo promedio: | C12: {=ROUND(AVERAGE(IF('Estado de Proyectos'!I:I="✅ Completado",'Estado de Proyectos'!H:H)),1) & "dias"} -> 31810.2dias
A13: Mas largo activo: | C13: {=MAX(IF('Estado de Proyectos'!I:I="🔄 En proceso",'Estado de Proyectos'!H:H))& "dias"} -> 0dias
A16: ALERTAS DE INVENTARIO
A17: Agotados | C17: =COUNTIF('Inventario Base'!J:J,"🔴 AGOTADO") -> 1 | D17: items
A18: Bajos | C18: =COUNTIF('Inventario Base'!J:J,"⚠️ BAJO") -> 34 | D18: items
A19: Suficientes | C19: =+COUNTIF('Inventario Base'!J:J, "✅ OK") -> 15 | D19: items
A24: CONSULTA DE PROYECTOS
A26: Proyecto | B26: Braker
A27: ID | B27: Area | C27: Material | D27: Tipo Pintura | E27: Color | F27: Codigo | G27: Fecha Delivery
A28: {=_xlfn._xlws.FILTER('RAW DATA PROYECTS'!B3:B60, 'RAW DATA PROYECTS'!A3:A60=B26,"Sin Areas")} -> 39 | B28: {=VLOOKUP(A28,'RAW DATA PROYECTS'!B3:M60,{2,4,5,6,7,12},FALSE)} -> Kitchen | C28: MDF | D28: Mohawk | E28: Simple White | F28: OC-117, M22-048 | G28: 0
A29: 40 | B29: {=VLOOKUP(A29,'RAW DATA PROYECTS'!B4:M59,{2,4,5,6,7,12},FALSE)} -> Kitchen | C29: Maple | D29: Mohawk | E29: Clear 40 | F29: 0 | G29: 0
A30: 41 | B30: {=VLOOKUP(A30,'RAW DATA PROYECTS'!B5:M60,{2,4,5,6,7,12},FALSE)} -> Laundry | C30: MDF | D30: Mohawk | E30: Simple White | F30: OC-117, M22-048 | G30: 0 | L30: =COUNTIF('Inventario Base'!J:J, "🔴 AGOTADO") -> 1
A31: 42 | B31: {=VLOOKUP(A31,'RAW DATA PROYECTS'!B6:M60,{2,4,5,6,7,12},FALSE)} -> Hall Bath | C31: Maple | D31: Mohawk | E31: Clear 40 | F31: 0 | G31: 0
A32: 43 | B32: {=VLOOKUP(A32,'RAW DATA PROYECTS'!B7:M60,{2,4,5,6,7,12},FALSE)} -> Primary Bath | C32: Cherry | D32: Evo | E32: Flat | F32: Base 4 | G32: 0
A33: 56 | B33: {=VLOOKUP(A33,'RAW DATA PROYECTS'!B8:M60,{2,4,5,6,7,12},FALSE)} -> 0 | C33: Maple | D33: Mohawk | E33: Clear 40 | F33: 0 | G33: 0

Sheet LISTA DE PENDIENTES
A2: Como esta funcionando el taller hoy? | E2: Se armaran estos dashboard de forma paralela cuando se arme la estructura de SQL y Python
A3: Operation health - Vista mensual | I3: 1.- Valio la pena implementar este sistema?
A4: Proyectos (Estado) | I4: SYSTEM IMPACT - 6 MESES
A5: Activos, Completados,Pendientes | I5: Errores de comunicacion
I6: Antes/Ahora
A7: Alertas de Inventario | I7: Desperdicio de material
I8: Antes/Ahora
A9: Eficiencia | I9: Tiempo consulta informacion | L9: El numero 1 en rojo sera puesto al final del proyecto
A10: Tiempo promedio | I10: Antes/Ahora
A11: Costo promedio
I12: ROI TOTAL: $$$
I14: Donde se esta atascadno el trabajo?
A15: Estamos desperdiciando materiales? | E15: Cuando se me va a acabar cada material? | I15: Process Bottlenecks
A16: Eficiencia de material - Pintura | E16: Inventiry Forecast | I16: Process Flow - Mensual
A17: ultimos 10 proyectos | E17: Material | F17: Stock | G17: Ronout | I17: Procesos, con dias
A18: Accuracy Rate | E18: Proximas Ordenes Sugeridas
A19: Desperdicio | I19: Bottleneck: Area x
E20: Basado en : | I20: Tiempo promedio
E21: Consumo promedio de los ultimos 30 dias, | I21: Causa
E22: 3 proyecos activos
I23: Recomendacion
A25: PENDIENTES
A27: DOCUMENTACION | D27: (1-2 SEMANAS MAX) | H27: BITACORA
A28: Escribir problemas | H28: Modificacion
A29: Documentar proceso | H29: Pasar formulas de proyectos antiguos, especificamente de estados de proyecto a registro de trabajos, donde se quede como "Terminados", para cerrar proyectos.
A30: Tomar fotos del antes (registros en papel)
A31: Explicar dolor operativo
A32: Explicar solucion
A33: Mostrar dashboard
A34: Mostrar estructura de hojas
A35: Explicar iimpacto esperado
A37: SUBIRLO A GITHUB | D37: (3-5 DIAS MAX)
A38: README Estructurado
A39: Carpeta/docs
A40: Screenshots bien presentados
A41: Version limpia del Excel
A42: Explicacion tecnica basica

Sheet Estado de Proyectos
A1: ESTADO DE PROYECTOS
A2: ID | B2: Proyecto | C2: Area | D2: Fecha Inicio | E2: Ultima Actividad | F2: Ultima Etapa | G2: Ultima Seccion | H2: Dias activo | I2: Estado
A3: ='RAW DATA PROYECTS'!B3 -> 1 | B3: =INDEX('RAW DATA PROYECTS'!A:A, MATCH(A3, 'RAW DATA PROYECTS'!B:B, 0)) -> Jen Herself. | D3: {=MIN(IF(Bitacora!$G:$G=B3, Bitacora!$B:$B))} -> 0 | E3: {=MAX(IF(Bitacora!$G:$G=B3, Bitacora!$C:$C))} -> 0 | F3: ='RAW DATA PROYECTS'!N3 -> Terminado | G3: =INDEX(Bitacora!$F:$F, MATCH(E3, Bitacora!$C:$C, 0)) -> #N/A | H3: =IF(F3="Delivery", E3-D3, TODAY()-E3) -> 46109 | I3: =IF(F3="Terminado", "✅ Completado", IF(F3="", "⏸️ Sin iniciar", "🔄 En proceso - " & F3 ) ) -> ✅ Completado
A4: ='RAW DATA PROYECTS'!B4 -> 2 | B4: =INDEX('RAW DATA PROYECTS'!A:A, MATCH(A4, 'RAW DATA PROYECTS'!B:B, 0)) -> Peetz | D4: {=MIN(IF(Bitacora!$G:$G=B4, Bitacora!$B:$B))} -> 0 | E4: {=MAX(IF(Bitacora!$G:$G=B4, Bitacora!$C:$C))} -> 0 | F4: ='RAW DATA PROYECTS'!N4 -> Terminado | G4: =INDEX(Bitacora!$F:$F, MATCH(E4, Bitacora!$C:$C, 0)) -> #N/A | H4: =IF(F4="Delivery", E4-D4, TODAY()-E4) -> 46109 | I4: =IF(F4="Terminado", "✅ Completado", IF(F4="", "⏸️ Sin iniciar", "🔄 En proceso - " & F4 ) ) -> ✅ Completado
A5: ='RAW DATA PROYECTS'!B5 -> 3 | B5: =INDEX('RAW DATA PROYECTS'!A:A, MATCH(A5, 'RAW DATA PROYECTS'!B:B, 0)) -> 0 | D5: {=MIN(IF(Bitacora!$G:$G=B5, Bitacora!$B:$B))} -> 0 | E5: {=MAX(IF(Bitacora!$G:$G=B5, Bitacora!$C:$C))} -> 46071 | F5: ='RAW DATA PROYECTS'!N5 -> Terminado | G5: =INDEX(Bitacora!$F:$F, MATCH(E5, Bitacora!$C:$C, 0)) -> Puertas/Tapas | H5: =IF(F5="Delivery", E5-D5, TODAY()-E5) -> 38 | I5: =IF(F5="Terminado", "✅ Completado", IF(F5="", "⏸️ Sin iniciar", "🔄 En proceso - " & F5 ) ) -> ✅ Completado
A6: ='RAW DATA PROYECTS'!B6 -> 4 | B6: =INDEX('RAW DATA PROYECTS'!A:A, MATCH(A6, 'RAW DATA PROYECTS'!B:B, 0)) -> Ramce | D6: {=MIN(IF(Bitacora!$G:$G=B6, Bitacora!$B:$B))} -> 0 | E6: {=MAX(IF(Bitacora!$G:$G=B6, Bitacora!$C:$C))} -> 0 | F6: ='RAW DATA PROYECTS'!N6 -> Terminado | G6: =INDEX(Bitacora!$F:$F, MATCH(E6, Bitacora!$C:$C, 0)) -> #N/A | H6: =IF(F6="Delivery", E6-D6, TODAY()-E6) -> 46109 | I6: =IF(F6="Terminado", "✅ Completado", IF(F6="", "⏸️ Sin iniciar", "🔄 En proceso - " & F6 ) ) -> ✅ Completado
A7: ='RAW DATA PROYECTS'!B7 -> 5 | B7: =INDEX('RAW DATA PROYECTS'!A:A, MATCH(A7, 'RAW DATA PROYECTS'!B:B, 0)) -> 0 | D7: {=MIN(IF(Bitacora!$G:$G=B7, Bitacora!$B:$B))} -> 0 | E7: {=MAX(IF(Bitacora!$G:$G=B7, Bitacora!$C:$C))} -> 46071 | F7: ='RAW DATA PROYECTS'!N7 -> Terminado | G7: =INDEX(Bitacora!$F:$F, MATCH(E7, Bitacora!$C:$C, 0)) -> Puertas/Tapas | H7: =IF(F7="Delivery", E7-D7, TODAY()-E7) -> 38 | I7: =IF(F7="Terminado", "✅ Completado", IF(F7="", "⏸️ Sin iniciar", "🔄 En proceso - " & F7 ) ) -> ✅ Completado
A8: ='RAW DATA PROYECTS'!B8 -> 6 | B8: =INDEX('RAW DATA PROYECTS'!A:A, MATCH(A8, 'RAW DATA PROYECTS'!B:B, 0)) -> 0 | D8: {=MIN(IF(Bitacora!$G:$G=B8, Bitacora!$B:$B))} -> 0 | E8: {=MAX(IF(Bitacora!$G:$G=B8, Bitacora!$C:$C))} -> 46071 | F8: ='RAW DATA PROYECTS'!N8 -> Terminado | G8: =INDEX(Bitacora!$F:$F, MATCH(E8, Bitacora!$C:$C, 0)) -> Puertas/Tapas | H8: =IF(F8="Delivery", E8-D8, TODAY()-E8) -> 38 | I8: =IF(F8="Terminado", "✅ Completado", IF(F8="", "⏸️ Sin iniciar", "🔄 En proceso - " & F8 ) ) -> ✅ Completado
A9: ='RAW DATA PROYECTS'!B9 -> 7 | B9: =INDEX('RAW DATA PROYECTS'!A:A, MATCH(A9, 'RAW DATA PROYECTS'!B:B, 0)) -> Baileanna | D9: {=MIN(IF(Bitacora!$G:$G=B9, Bitacora!$B:$B))} -> 0 | E9: {=MAX(IF(Bitacora!$G:$G=B9, Bitacora!$C:$C))} -> 0 | F9: ='RAW DATA PROYECTS'!N9 -> Terminado | G9: =INDEX(Bitacora!$F:$F, MATCH(E9, Bitacora!$C:$C, 0)) -> #N/A | H9: =IF(F9="Delivery", E9-D9, TODAY()-E9) -> 46109 | I9: =IF(F9="Terminado", "✅ Completado", IF(F9="", "⏸️ Sin iniciar", "🔄 En proceso - " & F9 ) ) -> ✅ Completado
A10: ='RAW DATA PROYECTS'!B10 -> 8 | B10: =INDEX('RAW DATA PROYECTS'!A:A, MATCH(A10, 'RAW DATA PROYECTS'!B:B, 0)) -> Shaw | D10: {=MIN(IF(Bitacora!$G:$G=B10, Bitacora!$B:$B))} -> 0 | E10: {=MAX(IF(Bitacora!$G:$G=B10, Bitacora!$C:$C))} -> 0 | F10: ='RAW DATA PROYECTS'!N10 -> Terminado | G10: =INDEX(Bitacora!$F:$F, MATCH(E10, Bitacora!$C:$C, 0)) -> #N/A | H10: =IF(F10="Delivery", E10-D10, TODAY()-E10) -> 46109 | I10: =IF(F10="Terminado", "✅ Completado", IF(F10="", "⏸️ Sin iniciar", "🔄 En proceso - " & F10 ) ) -> ✅ Completado
A11: ='RAW DATA PROYECTS'!B11 -> 9 | B11: =INDEX('RAW DATA PROYECTS'!A:A, MATCH(A11, 'RAW DATA PROYECTS'!B:B, 0)) -> Hubring | D11: {=MIN(IF(Bitacora!$G:$G=B11, Bitacora!$B:$B))} -> 0 | E11: {=MAX(IF(Bitacora!$G:$G=B11, Bitacora!$C:$C))} -> 0 | F11: ='RAW DATA PROYECTS'!N11 -> Terminado | G11: =INDEX(Bitacora!$F:$F, MATCH(E11, Bitacora!$C:$C, 0)) -> #N/A | H11: =IF(F11="Delivery", E11-D11, TODAY()-E11) -> 46109 | I11: =IF(F11="Terminado", "✅ Completado", IF(F11="", "⏸️ Sin iniciar", "🔄 En proceso - " & F11 ) ) -> ✅ Completado
A12: ='RAW DATA PROYECTS'!B12 -> 10 | B12: =INDEX('RAW DATA PROYECTS'!A:A, MATCH(A12, 'RAW DATA PROYECTS'!B:B, 0)) -> Dalerample | D12: {=MIN(IF(Bitacora!$G:$G=B12, Bitacora!$B:$B))} -> 0 | E12: {=MAX(IF(Bitacora!$G:$G=B12, Bitacora!$C:$C))} -> 0 | F12: ='RAW DATA PROYECTS'!N12 -> Terminado | G12: =INDEX(Bitacora!$F:$F, MATCH(E12, Bitacora!$C:$C, 0)) -> #N/A | H12: =IF(F12="Delivery", E12-D12, TODAY()-E12) -> 46109 | I12: =IF(F12="Terminado", "✅ Completado", IF(F12="", "⏸️ Sin iniciar", "🔄 En proceso - " & F12 ) ) -> ✅ Completado | K12: Notas
A13: ='RAW DATA PROYECTS'!B13 -> 11 | B13: =INDEX('RAW DATA PROYECTS'!A:A, MATCH(A13, 'RAW DATA PROYECTS'!B:B, 0)) -> Via Romero | D13: {=MIN(IF(Bitacora!$G:$G=B13, Bitacora!$B:$B))} -> 0 | E13: {=MAX(IF(Bitacora!$G:$G=B13, Bitacora!$C:$C))} -> 0 | F13: ='RAW DATA PROYECTS'!N13 -> Terminado | G13: =INDEX(Bitacora!$F:$F, MATCH(E13, Bitacora!$C:$C, 0)) -> #N/A | H13: =IF(F13="Delivery", E13-D13, TODAY()-E13) -> 46109 | I13: =IF(F13="Terminado", "✅ Completado", IF(F13="", "⏸️ Sin iniciar", "🔄 En proceso - " & F13 ) ) -> ✅ Completado | K13: Actualizar fechas
A14: ='RAW DATA PROYECTS'!B14 -> 12 | B14: =INDEX('RAW DATA PROYECTS'!A:A, MATCH(A14, 'RAW DATA PROYECTS'!B:B, 0)) -> Via Romero | D14: {=MIN(IF(Bitacora!$G:$G=B14, Bitacora!$B:$B))} -> 0 | E14: {=MAX(IF(Bitacora!$G:$G=B14, Bitacora!$C:$C))} -> 0 | F14: ='RAW DATA PROYECTS'!N14 -> Terminado | G14: =INDEX(Bitacora!$F:$F, MATCH(E14, Bitacora!$C:$C, 0)) -> #N/A | H14: =IF(F14="Delivery", E14-D14, TODAY()-E14) -> 46109 | I14: =IF(F14="Terminado", "✅ Completado", IF(F14="", "⏸️ Sin iniciar", "🔄 En proceso - " & F14 ) ) -> ✅ Completado
A15: ='RAW DATA PROYECTS'!B15 -> 13 | B15: =INDEX('RAW DATA PROYECTS'!A:A, MATCH(A15, 'RAW DATA PROYECTS'!B:B, 0)) -> Hardinger | D15: {=MIN(IF(Bitacora!$G:$G=B15, Bitacora!$B:$B))} -> 0 | E15: {=MAX(IF(Bitacora!$G:$G=B15, Bitacora!$C:$C))} -> 0 | F15: ='RAW DATA PROYECTS'!N15 -> Terminado | G15: =INDEX(Bitacora!$F:$F, MATCH(E15, Bitacora!$C:$C, 0)) -> #N/A | H15: =IF(F15="Delivery", E15-D15, TODAY()-E15) -> 46109 | I15: =IF(F15="Terminado", "✅ Completado", IF(F15="", "⏸️ Sin iniciar", "🔄 En proceso - " & F15 ) ) -> ✅ Completado
A16: ='RAW DATA PROYECTS'!B16 -> 14 | B16: =INDEX('RAW DATA PROYECTS'!A:A, MATCH(A16, 'RAW DATA PROYECTS'!B:B, 0)) -> Mahoney | D16: {=MIN(IF(Bitacora!$G:$G=B16, Bitacora!$B:$B))} -> 0 | E16: {=MAX(IF(Bitacora!$G:$G=B16, Bitacora!$C:$C))} -> 0 | F16: ='RAW DATA PROYECTS'!N16 -> Terminado | G16: =INDEX(Bitacora!$F:$F, MATCH(E16, Bitacora!$C:$C, 0)) -> #N/A | H16: =IF(F16="Delivery", E16-D16, TODAY()-E16) -> 46109 | I16: =IF(F16="Terminado", "✅ Completado", IF(F16="", "⏸️ Sin iniciar", "🔄 En proceso - " & F16 ) ) -> ✅ Completado
A17: ='RAW DATA PROYECTS'!B17 -> 15 | B17: =INDEX('RAW DATA PROYECTS'!A:A, MATCH(A17, 'RAW DATA PROYECTS'!B:B, 0)) -> Juan | D17: {=MIN(IF(Bitacora!$G:$G=B17, Bitacora!$B:$B))} -> 46069 | E17: {=MAX(IF(Bitacora!$G:$G=B17, Bitacora!$C:$C))} -> 46071 | F17: ='RAW DATA PROYECTS'!N17 -> Terminado | G17: =INDEX(Bitacora!$F:$F, MATCH(E17, Bitacora!$C:$C, 0)) -> Puertas/Tapas | H17: =IF(F17="Delivery", E17-D17, TODAY()-E17) -> 38 | I17: =IF(F17="Terminado", "✅ Completado", IF(F17="", "⏸️ Sin iniciar", "🔄 En proceso - " & F17 ) ) -> ✅ Completado
A18: ='RAW DATA PROYECTS'!B18 -> 16 | B18: =INDEX('RAW DATA PROYECTS'!A:A, MATCH(A18, 'RAW DATA PROYECTS'!B:B, 0)) -> Salvatierra | D18: {=MIN(IF(Bitacora!$G:$G=B18, Bitacora!$B:$B))} -> 0 | E18: {=MAX(IF(Bitacora!$G:$G=B18, Bitacora!$C:$C))} -> 0 | F18: ='RAW DATA PROYECTS'!N18 -> Terminado | G18: =INDEX(Bitacora!$F:$F, MATCH(E18, Bitacora!$C:$C, 0)) -> #N/A | H18: =IF(F18="Delivery", E18-D18, TODAY()-E18) -> 46109 | I18: =IF(F18="Terminado", "✅ Completado", IF(F18="", "⏸️ Sin iniciar", "🔄 En proceso - " & F18 ) ) -> ✅ Completado
A19: ='RAW DATA PROYECTS'!B19 -> 17 | B19: =INDEX('RAW DATA PROYECTS'!A:A, MATCH(A19, 'RAW DATA PROYECTS'!B:B, 0)) -> Belesis | D19: {=MIN(IF(Bitacora!$G:$G=B19, Bitacora!$B:$B))} -> 0 | E19: {=MAX(IF(Bitacora!$G:$G=B19, Bitacora!$C:$C))} -> 0 | F19: ='RAW DATA PROYECTS'!N19 -> Terminado | G19: =INDEX(Bitacora!$F:$F, MATCH(E19, Bitacora!$C:$C, 0)) -> #N/A | H19: =IF(F19="Delivery", E19-D19, TODAY()-E19) -> 46109 | I19: =IF(F19="Terminado", "✅ Completado", IF(F19="", "⏸️ Sin iniciar", "🔄 En proceso - " & F19 ) ) -> ✅ Completado
A20: ='RAW DATA PROYECTS'!B20 -> 18 | B20: =INDEX('RAW DATA PROYECTS'!A:A, MATCH(A20, 'RAW DATA PROYECTS'!B:B, 0)) -> Belesis | D20: {=MIN(IF(Bitacora!$G:$G=B20, Bitacora!$B:$B))} -> 0 | E20: {=MAX(IF(Bitacora!$G:$G=B20, Bitacora!$C:$C))} -> 0 | F20: ='RAW DATA PROYECTS'!N20 -> Terminado | G20: =INDEX(Bitacora!$F:$F, MATCH(E20, Bitacora!$C:$C, 0)) -> #N/A | H20: =IF(F20="Delivery", E20-D20, TODAY()-E20) -> 46109 | I20: =IF(F20="Terminado", "✅ Completado", IF(F20="", "⏸️ Sin iniciar", "🔄 En proceso - " & F20 ) ) -> ✅ Completado
A21: ='RAW DATA PROYECTS'!B21 -> 19 | B21: =INDEX('RAW DATA PROYECTS'!A:A, MATCH(A21, 'RAW DATA PROYECTS'!B:B, 0)) -> Belagio | D21: {=MIN(IF(Bitacora!$G:$G=B21, Bitacora!$B:$B))} -> 0 | E21: {=MAX(IF(Bitacora!$G:$G=B21, Bitacora!$C:$C))} -> 0 | F21: ='RAW DATA PROYECTS'!N21 -> Terminado | G21: =INDEX(Bitacora!$F:$F, MATCH(E21, Bitacora!$C:$C, 0)) -> #N/A | H21: =IF(F21="Delivery", E21-D21, TODAY()-E21) -> 46109 | I21: =IF(F21="Terminado", "✅ Completado", IF(F21="", "⏸️ Sin iniciar", "🔄 En proceso - " & F21 ) ) -> ✅ Completado
A22: ='RAW DATA PROYECTS'!B22 -> 20 | B22: =INDEX('RAW DATA PROYECTS'!A:A, MATCH(A22, 'RAW DATA PROYECTS'!B:B, 0)) -> Patrick | D22: {=MIN(IF(Bitacora!$G:$G=B22, Bitacora!$B:$B))} -> 0 | E22: {=MAX(IF(Bitacora!$G:$G=B22, Bitacora!$C:$C))} -> 0 | F22: ='RAW DATA PROYECTS'!N22 -> Terminado | G22: =INDEX(Bitacora!$F:$F, MATCH(E22, Bitacora!$C:$C, 0)) -> #N/A | H22: =IF(F22="Delivery", E22-D22, TODAY()-E22) -> 46109 | I22: =IF(F22="Terminado", "✅ Completado", IF(F22="", "⏸️ Sin iniciar", "🔄 En proceso - " & F22 ) ) -> ✅ Completado
A23: ='RAW DATA PROYECTS'!B23 -> 21 | B23: =INDEX('RAW DATA PROYECTS'!A:A, MATCH(A23, 'RAW DATA PROYECTS'!B:B, 0)) -> Clarkin | D23: {=MIN(IF(Bitacora!$G:$G=B23, Bitacora!$B:$B))} -> 0 | E23: {=MAX(IF(Bitacora!$G:$G=B23, Bitacora!$C:$C))} -> 0 | F23: ='RAW DATA PROYECTS'!N23 -> Terminado | G23: =INDEX(Bitacora!$F:$F, MATCH(E23, Bitacora!$C:$C, 0)) -> #N/A | H23: =IF(F23="Delivery", E23-D23, TODAY()-E23) -> 46109 | I23: =IF(F23="Terminado", "✅ Completado", IF(F23="", "⏸️ Sin iniciar", "🔄 En proceso - " & F23 ) ) -> ✅ Completado
A24: ='RAW DATA PROYECTS'!B24 -> 22 | B24: =INDEX('RAW DATA PROYECTS'!A:A, MATCH(A24, 'RAW DATA PROYECTS'!B:B, 0)) -> Sherman | D24: {=MIN(IF(Bitacora!$G:$G=B24, Bitacora!$B:$B))} -> 0 | E24: {=MAX(IF(Bitacora!$G:$G=B24, Bitacora!$C:$C))} -> 0 | F24: ='RAW DATA PROYECTS'!N24 -> Terminado | G24: =INDEX(Bitacora!$F:$F, MATCH(E24, Bitacora!$C:$C, 0)) -> #N/A | H24: =IF(F24="Delivery", E24-D24, TODAY()-E24) -> 46109 | I24: =IF(F24="Terminado", "✅ Completado", IF(F24="", "⏸️ Sin iniciar", "🔄 En proceso - " & F24 ) ) -> ✅ Completado
A25: ='RAW DATA PROYECTS'!B25 -> 23 | B25: =INDEX('RAW DATA PROYECTS'!A:A, MATCH(A25, 'RAW DATA PROYECTS'!B:B, 0)) -> Brad | D25: {=MIN(IF(Bitacora!$G:$G=B25, Bitacora!$B:$B))} -> 0 | E25: {=MAX(IF(Bitacora!$G:$G=B25, Bitacora!$C:$C))} -> 0 | F25: ='RAW DATA PROYECTS'!N25 -> Terminado | G25: =INDEX(Bitacora!$F:$F, MATCH(E25, Bitacora!$C:$C, 0)) -> #N/A | H25: =IF(F25="Delivery", E25-D25, TODAY()-E25) -> 46109 | I25: =IF(F25="Terminado", "✅ Completado", IF(F25="", "⏸️ Sin iniciar", "🔄 En proceso - " & F25 ) ) -> ✅ Completado
... A60: ='RAW DATA PROYECTS'!B60 -> 58 | B60: =INDEX('RAW DATA PROYECTS'!A:A, MATCH(A60, 'RAW DATA PROYECTS'!B:B, 0)) -> Kohar | D60: {=MIN(IF(Bitacora!$G:$G=B60, Bitacora!$B:$B))} -> 46069 | E60: {=MAX(IF(Bitacora!$G:$G=B60, Bitacora!$C:$C))} -> 46077 | F60: ='RAW DATA PROYECTS'!N60 -> Terminado | G60: =INDEX(Bitacora!$F:$F, MATCH(E60, Bitacora!$C:$C, 0)) -> Correccion | H60: =IF(F60="Delivery", E60-D60, TODAY()-E60) -> 32 | I60: =IF(F60="Terminado", "✅ Completado", IF(F60="", "⏸️ Sin iniciar", "🔄 En proceso - " & F60 ) ) -> ✅ Completado

Sheet Bitacora
A1: BITACORA
A2: Actividades | B2: Fecha Inicio | C2: Fecha Final | D2: Duracion dias | E2: Etapa | F2: Seccion | G2: Proyecto | H2: Area | I2: ID | J2: Encargado | K2: Notas: | M2: Proceso | N2: Avance
A3: 1 | B3: 46058 | C3: 46058 | D3: =MAX(1, C3-B3) -> 1 | E3: Rieles/Cajones | F3: Gabinetes | G3: Harrison | J3: Marco | M3: Preparado | N3: 0.1
A4: =A3+1 -> 2 | B4: 46057 | C4: 46057 | D4: =MAX(1, C4-B4) -> 1 | E4: Pintura Front | F4: Puertas/Tapas | G4: Braker | J4: Carlos | K4: Re ordenar puertas/tapas por correccion | M4: Sealer | N4: =N3+0.1 -> 0.2
A5: =A4+1 -> 3 | B5: 46058 | C5: 46059 | D5: =MAX(1, C5-B5) -> 1 | E5: Pintura Back | F5: Puertas/Tapas | G5: Braker | J5: Carlos | M5: Lijado sealer | N5: =N4+0.1 -> 0.3
A6: =A5+1 -> 4 | B6: 46056 | C6: 46059 | D6: =MAX(1, C6-B6) -> 3 | E6: Preparado | F6: Puertas/Tapas | G6: Harrison | J6: Will | M6: Pitura Front | N6: =N5+0.1 -> 0.4
A7: =A6+1 -> 5 | B7: 46059 | C7: 46059 | D7: =MAX(1, C7-B7) -> 1 | E7: Preparado | F7: Samples | G7: Proyecto | J7: Will | K7: Samples para napa | M7: Pintura Back | N7: =N6+0.1 -> 0.5
A8: =A7+1 -> 6 | B8: 46059 | C8: 46062 | D8: =MAX(1, C8-B8) -> 3 | E8: Sealer | F8: Puertas/Tapas | G8: Harrison | J8: Will | M8: Rieles/Cajones | N8: =N7+0.1 -> 0.6
A9: =A8+1 -> 7 | B9: 46062 | C9: 46062 | D9: =MAX(1, C9-B9) -> 1 | E9: Pintura Back | F9: Puertas/Tapas | G9: Harrison | J9: Will | M9: Figurar puertas/tapas | N9: =N8+0.1 -> 0.7
A10: =A9+1 -> 8 | B10: 46062 | C10: 46062 | D10: =MAX(1, C10-B10) -> 1 | E10: Pintura Front | F10: Puertas/Tapas | G10: Harrison | J10: Will | M10: Instalacion puertas/tapas | N10: =N9+0.1 -> 0.8
A11: =A10+1 -> 9 | B11: 46063 | C11: 46064 | D11: =MAX(1, C11-B11) -> 1 | E11: Figurar puertas/tapas | F11: Puertas/Tapas | G11: Harrison | J11: Will | K11: Retrasos externos (1 dia) | M11: Envolver | N11: =N10+0.1 -> 0.9
A12: =A11+1 -> 10 | B12: 46063 | C12: 46065 | D12: =MAX(1, C12-B12) -> 2 | E12: Instalacion puertas/tapas | F12: Puertas/Tapas | G12: Harrison | J12: Will | K12: Retrasos externos (1 dia) | M12: Delivery | N12: =N11+0.1 -> 1
A13: =A12+1 -> 11 | B13: 46066 | C13: 46066 | D13: =MAX(1, C13-B13) -> 1 | E13: Delivery | F13: Gabinetes | G13: Harrison | J13: Will
A14: =A13+1 -> 12 | B14: 46066 | C14: 46066 | D14: =MAX(1, C14-B14) -> 1 | E14: Proceso Completo | F14: Fillers | G14: Braker | J14: Will | K14: Pendientes | M14: Notas
A15: =A14+1 -> 13 | B15: 46066 | C15: 46066 | D15: =MAX(1, C15-B15) -> 1 | E15: Proceso Completo | F15: Puertas/Tapas | G15: Braker | J15: Will | K15: Pendientes | M15: Actualizar Proyectos, y vincularlos con Id para mejorar el estado de proyectos
A16: =A15+1 -> 14 | B16: 46066 | C16: 46066 | D16: =MAX(1, C16-B16) -> 1 | E16: Proceso Completo | F16: Fillers | G16: Aravind | J16: Will | K16: Pendientes
A17: =A16+1 -> 15 | B17: 46066 | C17: 46066 | D17: =MAX(1, C17-B17) -> 1 | E17: Proceso Completo | F17: Puertas/Tapas | G17: BlackWell | J17: Will | K17: Pendientes
A18: =A17+1 -> 16 | B18: 46067 | C18: 46067 | D18: =MAX(1, C18-B18) -> 1 | E18: Delivery | F18: Correccion | G18: Braker | J18: Will | K18: Instalacion de pendientes/correcciones
A19: =A18+1 -> 17 | B19: 46069 | C19: 46069 | D19: =MAX(1, C19-B19) -> 1 | E19: Preparado | F19: Puertas/Tapas | G19: Eucalyptus | J19: Marco | K19: Re ordenamiento puertas/tapas
A20: =A19+1 -> 18 | B20: 46069 | C20: 46069 | D20: =MAX(1, C20-B20) -> 1 | E20: Sealer | F20: Puertas/Tapas | G20: Eucalyptus | J20: Marco
A21: =A20+1 -> 19 | B21: 46069 | C21: 46069 | D21: =MAX(1, C21-B21) -> 1 | E21: Preparado | F21: Gabinetes | G21: Braker | J21: Will | K21: Gabinetes pendientes
A22: =A21+1 -> 20 | B22: 46069 | C22: 46069 | D22: =MAX(1, C22-B22) -> 1 | E22: Sealer | F22: Gabinetes | G22: Braker | J22: Will
A23: =A22+1 -> 21 | B23: 46069 | C23: 46071 | D23: =MAX(1, C23-B23) -> 2 | E23: Preparado | F23: Puertas/Tapas | G23: Juan | J23: Carlos
A24: =A23+1 -> 22 | B24: 46069 | C24: 46071 | D24: =MAX(1, C24-B24) -> 2 | E24: Preparado | F24: Puertas/Tapas | G24: Neville | J24: Carlos
A25: =A24+1 -> 23 | B25: 46069 | C25: 46071 | D25: =MAX(1, C25-B25) -> 2 | E25: Preparado | F25: Puertas/Tapas | G25: Kohar | J25: Carlos
A26: =A25+1 -> 24 | B26: 46069 | C26: 46071 | D26: =MAX(1, C26-B26) -> 2 | E26: Preparado | F26: Puertas/Tapas | J26: Carlos
A27: =A26+1 -> 25 | B27: 46069 | C27: 46070 | D27: =MAX(1, C27-B27) -> 1 | E27: Preparado | F27: Toe kick | G27: Braker | J27: Marco
A28: =A27+1 -> 26 | B28: 46069 | C28: 46070 | D28: =MAX(1, C28-B28) -> 1 | E28: Sealer | F28: Toe kick | G28: Braker | J28: Marco
A29: =A28+1 -> 27 | B29: 46069 | C29: 46070 | D29: =MAX(1, C29-B29) -> 1 | E29: Preparado | F29: Molding | G29: Braker | J29: Marco | K29: Molding natural
A30: =A29+1 -> 28 | B30: 46069 | C30: 46070 | D30: =MAX(1, C30-B30) -> 1 | E30: Sealer | F30: Molding | G30: Braker | J30: Marco
A31: =A30+1 -> 29 | B31: 46069 | C31: 46070 | D31: =MAX(1, C31-B31) -> 1 | E31: Preparado | F31: Molding | G31: Braker | J31: Marco | K31: Molding color
A32: =A31+1 -> 30 | B32: 46069 | C32: 46070 | D32: =MAX(1, C32-B32) -> 1 | E32: Sealer | F32: Molding | G32: Braker | J32: Marco
A33: =A32+1 -> 31 | B33: 46069 | C33: 46070 | D33: =MAX(1, C33-B33) -> 1 | E33: Preparado | F33: Puertas/Tapas | G33: Eucalyptus | J33: Will | K33: Remplazo puertas
A34: =A33+1 -> 32 | B34: 46070 | C34: 46070 | D34: =MAX(1, C34-B34) -> 1 | E34: Sealer | F34: Puertas/Tapas | G34: Eucalyptus | J34: Will
A35: =A34+1 -> 33 | B35: 46070 | C35: 46070 | D35: =MAX(1, C35-B35) -> 1 | E35: Lijado Sealer | F35: Puertas/Tapas | G35: Eucalyptus | J35: Will
A36: =A35+1 -> 34 | B36: 46070 | C36: 46070 | D36: =MAX(1, C36-B36) -> 1 | E36: Pintura Back | F36: Puertas/Tapas | G36: Eucalyptus | J36: Will
A37: =A36+1 -> 35 | B37: 46071 | C37: 46071 | D37: =MAX(1, C37-B37) -> 1 | E37: Pintura Front | F37: Puertas/Tapas | G37: Eucalyptus | J37: Will
A38: =A37+1 -> 36 | B38: 46072 | C38: 46072 | D38: =MAX(1, C38-B38) -> 1 | E38: Sealer | F38: Puertas/Tapas | G38: Kohar | J38: Marco
A39: =A38+1 -> 37 | B39: 46072 | C39: 46073 | D39: =MAX(1, C39-B39) -> 1 | E39: Sealer | F39: Puertas/Tapas | G39: Neville | J39: Will
A40: =A39+1 -> 38 | B40: 46073 | C40: 46073 | D40: =MAX(1, C40-B40) -> 1 | E40: Sealer | F40: Gabinetes | G40: Neville | J40: Will
...

Sheet RAW DATA PROYECTS
A1: DATA BASE PROYECTS
A2: Proyecto | B2: ID | C2: Area | D2: Seccion Trabajada | E2: Materiales | F2: Tipo Pintura | G2: Colores | H2: Codigos | I2: Stain / Glaze | J2: Nombre | K2: Codigo | L2: Fecha Inicio | M2: Fecha Delivery | N2: Estado de proyecto | O2: Notas
A3: Jen Herself. | B3: 1 | C3: Fireplace | D3: Completo | E3: MDF | F3: Mohawk | G3: Simple White | H3: OC-117, M21-026 | N3: Terminado
A4: Peetz | B4: 2 | C4: Kitchen | D4: Completo | E4: MDF | F4: Mohawk | G4: Cloud White | H4: OC-130, M22-028 | N4: Terminado
B5: 3 | D5: Completo | E5: MDF | F5: Mohawk | G5: Decorations White | H5: PM-3, M17-072 | N5: Terminado
A6: Ramce | B6: 4 | D6: Completo | E6: MDF | F6: Mohawk | G6: Parish White | H6: CW-15,M24-024 | N6: Terminado
B7: 5 | D7: Completo | E7: MDF | F7: Mohawk | G7: Stonington Gray | H7: HC-170, M25-021 | N7: Terminado
B8: 6 | D8: Completo | E8: MDF | F8: Mohawk | G8: Yorktown Green | H8: HC-133, M25-022 | N8: Terminado
A9: Baileanna | B9: 7 | D9: Completo | E9: MDF | F9: Mohawk | G9: - | H9: CSP-620, M24-067 | N9: Terminado
A10: Shaw | B10: 8 | D10: Completo | E10: MDF | F10: Mohawk | G10: Pure White | H10: SW-7005, M25-080 | N10: Terminado
A11: Hubring | B11: 9 | D11: Completo | E11: MDF | F11: Mohawk | G11: Match Sample Board | H11: M25-047 | N11: Terminado
A12: Dalerample | B12: 10 | D12: Completo | E12: MDF | F12: Mohawk | G12: Glacier White | H12: M25-002, OC-37 | N12: Terminado
A13: Via Romero | B13: 11 | C13: Kitchen | D13: Completo | E13: MDF | F13: Mohawk | G13: Swiss Coffee | H13: M17-044 KM | N13: Terminado
A14: Via Romero | B14: 12 | C14: Bathroom | D14: Completo | E14: MDF | F14: Mohawk | G14: Swiss Coffee | H14: M17-044 KM | N14: Terminado
A15: Hardinger | B15: 13 | D15: Completo | E15: MDF | F15: Envirolak | G15: - | N15: Terminado
A16: Mahoney | B16: 14 | D16: Completo | E16: MDF | F16: Envirolak | G16: - | N16: Terminado
A17: Juan | B17: 15 | D17: Completo | E17: MDF | F17: Envirolak | G17: - | N17: Terminado
A18: Salvatierra | B18: 16 | D18: Completo | E18: MDF | F18: Mohawk | G18: Swiss Coffee | N18: Terminado
A19: Belesis | B19: 17 | D19: Completo | E19: WhiteOak | F19: Mohawk | G19: Clear40 | N19: Terminado
A20: Belesis | B20: 18 | D20: Completo | E20: MDF | F20: Mohawk | G20: Kendall Charcoal | H20: HC-166, M25-027 | N20: Terminado
A21: Belagio | B21: 19 | D21: Completo | E21: WhiteOak | F21: Evo | G21: Clear Satin | N21: Terminado
A22: Patrick | B22: 20 | D22: Completo | E22: MDF | F22: Mohawk | G22: Swiss Coffee | H22: M25-026, OC-45 | N22: Terminado
A23: Clarkin | B23: 21 | D23: Completo | E23: MDF | F23: Evo | G23: Smokey Tope | N23: Terminado
A24: Sherman | B24: 22 | D24: Completo | E24: MDF | F24: Envirolak | G24: Black Paint | H24: DUB 24-612 #2 | N24: Terminado
A25: Brad | B25: 23 | D25: Completo | E25: Alder | F25: Mohawk | G25: Clear40 | I25: Saman Wood Stain. | J25: Golden Wheat 111 | N25: Terminado
A26: Hubring | B26: 24 | D26: Completo | E26: MDF | F26: Mohawk | G26: - | N26: Terminado
A27: Patrick | B27: 25 | D27: Completo | E27: WhiteOak | F27: Mohawk | G27: Clear40 | I27: Other | J27: Main Wax, Base Water | N27: Terminado
A28: Packtor | B28: 26 | D28: Completo | E28: Birch | F28: Mohawk | G28: Clear40 | I28: Glazier Mohak | J28: Raw Umber | K28: M504-01436 | N28: Terminado
A29: Packtor | B29: 27 | D29: Completo | E29: MDF | F29: Mohawk | G29: Silver Gray | H29: M25-061,2131-60 | N29: Terminado
A30: Bellagio | B30: 28 | D30: Completo | E30: MDF | F30: Mohawk | G30: SimpleWhite | N30: Terminado
A31: Stratigios | B31: 29 | D31: Completo | E31: MDF | F31: Mohawk | G31: White Dove | H31: OC-17, M19-031 | N31: Terminado
A32: San Francisco | B32: 30 | D32: Completo | E32: MDF | F32: Mohawk | G32: Simple White | N32: Terminado
A33: San Francisco | B33: 31 | D33: Completo | E33: Walnaut | F33: Mohawk | G33: Clear 40 | I33: Saman Wood Stain | J33: TM Brown Satin | K33: M394000 | N33: Terminado
A34: Shaw | B34: 32 | D34: Completo | E34: MDF | F34: Mohawk | G34: Pure White | H34: M25-080 | N34: Terminado
A35: Jura | B35: 33 | D35: Completo | E35: MDF | F35: Mohawk | G35: Chantilly Lace | H35: OC-65, M25-085 | N35: Terminado
A36: Jura | B36: 34 | D36: Completo | E36: Alder | F36: Mohawk | G36: Clear 40 | I36: Old Masters | J36: Glassier White | K36: M504-2026 | N36: Terminado
A37: Emtage | B37: 35 | D37: Completo | E37: MDF | F37: Mohawk | G37: Simple White | N37: Terminado
A38: Belesis | B38: 36 | D38: Completo | E38: MDF | F38: Mohawk | G38: Natural Cream | H38: M25-091, OC-14 | N38: Terminado
A39: Jura | B39: 37 | D39: Completo | E39: Alder | F39: Evo | G39: Flat | H39: ECL-0010-5 | N39: Terminado
A40: Maihorana | B40: 38 | D40: Completo | E40: WhiteOak | F40: Evo | G40: Flat | H40: ECL-0030-5 | N40: Terminado
...

Sheet Calculos Material
A1: Numero | B1: Proyecto | C1: Area | D1: Materiales | E1: Tipo Pintura | F1: Colores | G1: Sq/ft Cabs | H1: Sq/ft Door | I1: Rango Tecnico | J1: Expectativa
A2: 1 | B2: Jen Herself. | C2: Fireplace | D2: MDF | E2: Mohawk | F2: Simple White | G2: 10 | H2: 100 | I2: 262.26 | J2: =(G2+H2)/I2 -> 0.4194311
A3: =1+A2 -> 2 | B3: Dalerample | C3: - | D3: MDF | E3: Mohawk | F3: Glacier White | G3: - | J3: =(G3+H3)/I3 -> #VALUE!
A4: =1+A3 -> 3 | B4: Via Romero | C4: Kitchen, Bathrooms | D4: MDF | E4: Mohawk | F4: Swiss Coffee | G4: - | J4: =(G4+H4)/I4 -> #VALUE!
A5: =1+A4 -> 4 | B5: Hardinger | C5: - | D5: MDF | E5: Envirolak | F5: - | J5: =(G5+H5)/I5 -> #DIV/0!
A6: =1+A5 -> 5 | B6: Mahoney | C6: - | D6: MDF | E6: Envirolak | F6: - | J6: =(G6+H6)/I6 -> #DIV/0!
A7: =1+A6 -> 6 | B7: Juan | C7: - | D7: MDF | E7: Envirolak | F7: - | J7: =(G7+H7)/I7 -> #DIV/0!
A8: =1+A7 -> 7 | B8: Salvatierra | C8: - | D8: MDF | E8: Mohawk | F8: Swiss Coffee | J8: =(G8+H8)/I8 -> #DIV/0!
A9: =1+A8 -> 8 | B9: Belesis | C9: - | D9: WhiteOak | E9: Mohawk | F9: Clear40 | J9: =(G9+H9)/I9 -> #DIV/0!
A10: =1+A9 -> 9 | B10: Belesis | C10: - | D10: MDF | E10: Mohawk | F10: Kendall Charcoal | J10: =(G10+H10)/I10 -> #DIV/0!
A11: =1+A10 -> 10 | B11: Belagio | C11: - | D11: WhiteOak | E11: Evo | F11: Clear Satin | J11: =(G11+H11)/I11 -> #DIV/0!
A12: =1+A11 -> 11 | B12: Patrick | C12: - | D12: MDF | E12: Mohawk | F12: Swiss Coffee | J12: =(G12+H12)/I12 -> #DIV/0!
A13: =1+A12 -> 12 | B13: Clarkin | C13: - | D13: MDF | E13: Evo | F13: Smokey Tope | J13: =(G13+H13)/I13 -> #DIV/0!
A14: =1+A13 -> 13 | B14: Sherman | C14: - | D14: MDF | E14: Envirolak | F14: Black Paint | J14: =(G14+H14)/I14 -> #DIV/0!
A15: =1+A14 -> 14 | B15: Brad | C15: - | D15: Alder | E15: Mohawk | F15: Clear40 | J15: =(G15+H15)/I15 -> #DIV/0!
A16: =1+A15 -> 15 | B16: Hubring | C16: - | D16: MDF | E16: Mohawk | F16: PENDING | J16: =(G16+H16)/I16 -> #DIV/0!
... A36: =1+A35 -> 35 | B36: Belesis | C36: Fireplace | D36: MDF | E36: Mohawk | F36: Natural Cream | J36: =(G36+H36)/I36 -> #DIV/0!
A37: =1+A36 -> 36 | B37: Juan Farias | D37: MDF | E37: Mohawk | F37: Swiss Coffe | J37: =(G37+H37)/I37 -> #DIV/0!
A38: =1+A37 -> 37 | B38: BlackWell | D38: MDF | E38: Mohawk | F38: White Dove | J38: =(G38+H38)/I38 -> #DIV/0!
A39: =1+A38 -> 38 | B39: BlackWell | D39: Walnaut | E39: Mohawk | F39: Clear 40 | J39: =(G39+H39)/I39 -> #DIV/0!
A40: =1+A39 -> 39 | B40: Via Romero | D40: Maple | E40: Mohawk | F40: Clear 40 | J40: =(G40+H40)/I40 -> #DIV/0!
A41: =1+A40 -> 40 | B41: Aravind | D41: MDF | E41: Mohak | F41: Fresh Olive | J41: =(G41+H41)/I41 -> #DIV/0!
A42: =1+A41 -> 41 | B42: Aravind | D42: MDF | E42: Mohak | F42: Jet Black | J42: =(G42+H42)/I42 -> #DIV/0!
A43: =1+A42 -> 42 | B43: Eucalyptus | D43: WhiteOak | E43: Evo | F43: Satin | J43: =(G43+H43)/I43 -> #DIV/0!
A44: =1+A43 -> 43 | B44: Liane | D44: MDF | E44: Mohawk | F44: Feather Gray | J44: =(G44+H44)/I44 -> #DIV/0!
A45: =1+A44 -> 44 | B45: Liane | D45: WhiteOak | E45: Evo | F45: Satin | J45: =(G45+H45)/I45 -> #DIV/0!
A46: =1+A45 -> 45 | B46: Harrison | D46: WhiteOak | E46: Evo | F46: Satin | J46: =(G46+H46)/I46 -> #DIV/0!
A47: =1+A46 -> 46 | B47: Braker | D47: Maple | E47: Mohak | F47: Clear 40 | H47: =((250.42*0.0625)*4)+((98.13*4)) -> 455.125 | I47: 262.26 | J47: =(G47+H47)/I47 -> 1.7353962
A48: =1+A47 -> 47 | J48: =(G48+H48)/I48 -> #DIV/0!
A49: =1+A48 -> 48 | J49: =(G49+H49)/I49 -> #DIV/0!
A50: =1+A49 -> 49
A51: =1+A50 -> 50
A52: =1+A51 -> 51
A53: =1+A52 -> 52
A54: =1+A53 -> 53
A55: =1+A54 -> 54

Sheet Consumo Material
A1: Proyectos | B1: Expectativa | C1: Practica Back 1 | D1: Practica Back 2 | E1: Practica Front 1 | F1: Practica Front 2 | H1: Diferencia | I1: Escala
A2: {='Calculos Material'!B2:B47} -> Jen Herself. | B2: =('Calculos Material'!G2+'Calculos Material'!H2)/'Calculos Material'!I2 -> 0.4194311 | C2: 0.25 | D2: 0.22 | E2: 0.21 | F2: 0.2 | H2: =(C2+D2+E2+F2)-B2 -> 0.4605689 | I2: =H2 -> 0.4605689
A3: Dalerample | B3: =('Calculos Material'!G3+'Calculos Material'!H3)/'Calculos Material'!I3 -> #VALUE! | H3: =(C3+D3+E3+F3)-B3 -> #VALUE! | I3: =H3 -> #VALUE!
A4: Via Romero | B4: =('Calculos Material'!G4+'Calculos Material'!H4)/'Calculos Material'!I4 -> #VALUE! | H4: =(C4+D4+E4+F4)-B4 -> #VALUE! | I4: =H4 -> #VALUE!
A5: Hardinger | B5: =('Calculos Material'!G5+'Calculos Material'!H5)/'Calculos Material'!I5 -> #DIV/0! | H5: =(C5+D5+E5+F5)-B5 -> #DIV/0! | I5: =H5 -> #DIV/0!
A6: Mahoney | B6: =('Calculos Material'!G6+'Calculos Material'!H6)/'Calculos Material'!I6 -> #DIV/0! | H6: =(C6+D6+E6+F6)-B6 -> #DIV/0! | I6: =H6 -> #DIV/0!
A7: Juan | B7: =('Calculos Material'!G7+'Calculos Material'!H7)/'Calculos Material'!I7 -> #DIV/0! | H7: =(C7+D7+E7+F7)-B7 -> #DIV/0! | I7: =H7 -> #DIV/0!
A8: Salvatierra | B8: =('Calculos Material'!G8+'Calculos Material'!H8)/'Calculos Material'!I8 -> #DIV/0! | H8: =(C8+D8+E8+F8)-B8 -> #DIV/0! | I8: =H8 -> #DIV/0!
A9: Belesis | B9: =('Calculos Material'!G9+'Calculos Material'!H9)/'Calculos Material'!I9 -> #DIV/0! | H9: =(C9+D9+E9+F9)-B9 -> #DIV/0! | I9: =H9 -> #DIV/0!
A10: Belesis | B10: =('Calculos Material'!G10+'Calculos Material'!H10)/'Calculos Material'!I10 -> #DIV/0! | H10: =(C10+D10+E10+F10)-B10 -> #DIV/0! | I10: =H10 -> #DIV/0!
A11: Belagio | B11: =('Calculos Material'!G11+'Calculos Material'!H11)/'Calculos Material'!I11 -> #DIV/0! | H11: =(C11+D11+E11+F11)-B11 -> #DIV/0! | I11: =H11 -> #DIV/0!
A12: Patrick | B12: =('Calculos Material'!G12+'Calculos Material'!H12)/'Calculos Material'!I12 -> #DIV/0! | H12: =(C12+D12+E12+F12)-B12 -> #DIV/0! | I12: =H12 -> #DIV/0!
A13: Clarkin | B13: =('Calculos Material'!G13+'Calculos Material'!H13)/'Calculos Material'!I13 -> #DIV/0! | H13: =(C13+D13+E13+F13)-B13 -> #DIV/0! | I13: =H13 -> #DIV/0!
A14: Sherman | B14: =('Calculos Material'!G14+'Calculos Material'!H14)/'Calculos Material'!I14 -> #DIV/0! | H14: =(C14+D14+E14+F14)-B14 -> #DIV/0! | I14: =H14 -> #DIV/0!
... A46: Harrison | B46: =('Calculos Material'!G46+'Calculos Material'!H46)/'Calculos Material'!I46 -> #DIV/0! | H46: =(C46+D46+E46+F46)-B46 -> #DIV/0! | I46: =H46 -> #DIV/0!
A47: Braker | B47: =('Calculos Material'!G47+'Calculos Material'!H47)/'Calculos Material'!I47 -> 1.7353962 | C47: 3 | D47: 1.8 | E47: 2 | F47: 2 | H47: =(C47+D47+E47+F47)-B47 -> 7.0646038 | I47: =H47 -> 7.0646038
B48: =('Calculos Material'!G48+'Calculos Material'!H48)/'Calculos Material'!I48 -> #DIV/0! | H48: =(C48+D48+E48+F48)-B48 -> #DIV/0! | I48: =H48 -> #DIV/0!
B49: =('Calculos Material'!G49+'Calculos Material'!H49)/'Calculos Material'!I49 -> #DIV/0! | H49: =(C49+D49+E49+F49)-B49 -> #DIV/0! | I49: =H49 -> #DIV/0!

Sheet Inventario Base
A1: INVENTARIO BASE
A2: ID | B2: Categoría | C2: Material/Producto | D2: Color/Tipo | E2: Unidad | F2: Stock Inicial | G2: Stok Actual | H2: Ubicacion | I2: Stock Minimo | J2: Estado
A3: 1 | B3: Consumibles | C3: Toallas | D3: Multi Proposito | E3: Cjas | F3: 1.25 | G3: =SUMIF('Inventario E-S'!C:C, C3, 'Inventario E-S'!D:D) - SUMIF('Inventario E-S'!C:C, C3, 'Inventario E-S'!E:E)+F3 -> 2.25 | H3: Estante Principal | I3: 0.25 | J3: =IF(G3<=0,"🔴 AGOTADO",IF(G3<=I3,"⚠️ BAJO","✅ OK")) -> ✅ OK
A4: =A3+1 -> 2 | B4: Consumibles | C4: Papel | D4: Mediano | E4: Pzas | F4: 2 | G4: =SUMIF('Inventario E-S'!C:C, C4, 'Inventario E-S'!D:D) - SUMIF('Inventario E-S'!C:C, C4, 'Inventario E-S'!E:E)+F4 -> 7 | I4: =I3+1 -> 1.25 | J4: =IF(G4<=0,"🔴 AGOTADO",IF(G4<=I4,"⚠️ BAJO","✅ OK")) -> ✅ OK
A5: =A4+1 -> 3 | B5: Consumibles | C5: Papel | D5: Grande | E5: Pzas | F5: 0 | G5: =SUMIF('Inventario E-S'!C:C, C5, 'Inventario E-S'!D:D) - SUMIF('Inventario E-S'!C:C, C5, 'Inventario E-S'!E:E)+F5 -> 5 | I5: =I4+1 -> 2.25 | J5: =IF(G5<=0,"🔴 AGOTADO",IF(G5<=I5,"⚠️ BAJO","✅ OK")) -> ✅ OK | L5: Insumo
A6: =A5+1 -> 4 | B6: Consumibles | C6: Plasticos | D6: Rollo | E6: Pzas | F6: 2 | G6: =SUMIF('Inventario E-S'!C:C, C6, 'Inventario E-S'!D:D) - SUMIF('Inventario E-S'!C:C, C6, 'Inventario E-S'!E:E)+F6 -> 12 | I6: =I5+1 -> 3.25 | J6: =IF(G6<=0,"🔴 AGOTADO",IF(G6<=I6,"⚠️ BAJO","✅ OK")) -> ✅ OK | L6: Equipo no desechable, rieles, clips, etc
A7: =A6+1 -> 5 | B7: Consumibles | C7: Tape | D7: Azul | E7: Pzas | F7: 4 | G7: =SUMIF('Inventario E-S'!C:C, C7, 'Inventario E-S'!D:D) - SUMIF('Inventario E-S'!C:C, C7, 'Inventario E-S'!E:E)+F7 -> 4 | I7: =I6+1 -> 4.25 | J7: =IF(G7<=0,"🔴 AGOTADO",IF(G7<=I7,"⚠️ BAJO","✅ OK")) -> ⚠️ BAJO
A8: =A7+1 -> 6 | B8: Consumibles | C8: Tape | D8: Naranja | E8: Pzas | F8: 4 | G8: =SUMIF('Inventario E-S'!C:C, C8, 'Inventario E-S'!D:D) - SUMIF('Inventario E-S'!C:C, C8, 'Inventario E-S'!E:E)+F8 -> 4 | I8: =I7+1 -> 5.25 | J8: =IF(G8<=0,"🔴 AGOTADO",IF(G8<=I8,"⚠️ BAJO","✅ OK")) -> ⚠️ BAJO
A9: =A8+1 -> 7 | B9: Consumibles | C9: Lija Rectangular | D9: 150 | E9: Pzas | F9: 40 | G9: =SUMIF('Inventario E-S'!C:C, C9, 'Inventario E-S'!D:D) - SUMIF('Inventario E-S'!C:C, C9, 'Inventario E-S'!E:E)+F9 -> 40 | I9: =I8+1 -> 6.25 | J9: =IF(G9<=0,"🔴 AGOTADO",IF(G9<=I9,"⚠️ BAJO","✅ OK")) -> ✅ OK
A10: =A9+1 -> 8 | B10: Consumibles | C10: Lija Rectangular | D10: 220 | E10: Pzas | F10: 40 | G10: =SUMIF('Inventario E-S'!C:C, C10, 'Inventario E-S'!D:D) - SUMIF('Inventario E-S'!C:C, C10, 'Inventario E-S'!E:E)+F10 -> 40 | I10: =I9+1 -> 7.25 | J10: =IF(G10<=0,"🔴 AGOTADO",IF(G10<=I10,"⚠️ BAJO","✅ OK")) -> ✅ OK | L10: Consumible
A11: =A10+1 -> 9 | B11: Consumibles | C11: Lija Rectangular | D11: 320 | E11: Pzas | F11: 40 | G11: =SUMIF('Inventario E-S'!C:C, C11, 'Inventario E-S'!D:D) - SUMIF('Inventario E-S'!C:C, C11, 'Inventario E-S'!E:E)+F11 -> 40 | I11: =I10+1 -> 8.25 | J11: =IF(G11<=0,"🔴 AGOTADO",IF(G11<=I11,"⚠️ BAJO","✅ OK")) -> ✅ OK | L11: Lijas, Toallas, Desechabe
A12: =A11+1 -> 10 | B12: Consumibles | C12: Lija Rectangular | D12: 360 | E12: Pzas | F12: 40 | G12: =SUMIF('Inventario E-S'!C:C, C12, 'Inventario E-S'!D:D) - SUMIF('Inventario E-S'!C:C, C12, 'Inventario E-S'!E:E)+F12 -> 40 | I12: 2 | J12: =IF(G12<=0,"🔴 AGOTADO",IF(G12<=I12,"⚠️ BAJO","✅ OK")) -> ✅ OK
A13: =A12+1 -> 11 | B13: Consumibles | C13: Lija Circular | D13: 150 | E13: Pzas | F13: 7 | G13: =SUMIF('Inventario E-S'!C:C, C13, 'Inventario E-S'!D:D) - SUMIF('Inventario E-S'!C:C, C13, 'Inventario E-S'!E:E)+F13 -> 7 | I13: =I12+1 -> 3 | J13: =IF(G13<=0,"🔴 AGOTADO",IF(G13<=I13,"⚠️ BAJO","✅ OK")) -> ✅ OK
A14: =A13+1 -> 12 | B14: Consumibles | C14: Lija Circular | D14: 220 | E14: Pzas | F14: 7 | G14: =SUMIF('Inventario E-S'!C:C, C14, 'Inventario E-S'!D:D) - SUMIF('Inventario E-S'!C:C, C14, 'Inventario E-S'!E:E)+F14 -> 7 | I14: =I13+1 -> 4 | J14: =IF(G14<=0,"🔴 AGOTADO",IF(G14<=I14,"⚠️ BAJO","✅ OK")) -> ✅ OK
A15: =A14+1 -> 13 | B15: Consumibles | C15: Lija Circular | D15: 320 | E15: Pzas | F15: 0 | G15: =SUMIF('Inventario E-S'!C:C, C15, 'Inventario E-S'!D:D) - SUMIF('Inventario E-S'!C:C, C15, 'Inventario E-S'!E:E)+F15 -> 0 | I15: =I14+1 -> 5 | J15: =IF(G15<=0,"🔴 AGOTADO",IF(G15<=I15,"⚠️ BAJO","✅ OK")) -> 🔴 AGOTADO
A16: =A15+1 -> 14 | B16: Consumibles | C16: Lija Circular | D16: Roja | E16: Pzas | F16: 7 | G16: =SUMIF('Inventario E-S'!C:C, C16, 'Inventario E-S'!D:D) - SUMIF('Inventario E-S'!C:C, C16, 'Inventario E-S'!E:E)+F16 -> 7 | I16: =I15+1 -> 6 | J16: =IF(G16<=0,"🔴 AGOTADO",IF(G16<=I16,"⚠️ BAJO","✅ OK")) -> ✅ OK
A17: =A16+1 -> 15 | B17: Consumibles | C17: Guantes | D17: Azules | E17: Cjas | F17: 7 | G17: =SUMIF('Inventario E-S'!C:C, C17, 'Inventario E-S'!D:D) - SUMIF('Inventario E-S'!C:C, C17, 'Inventario E-S'!E:E)+F17 -> 7 | I17: =I16+1 -> 7 | J17: =IF(G17<=0,"🔴 AGOTADO",IF(G17<=I17,"⚠️ BAJO","✅ OK")) -> ⚠️ BAJO
A18: =A17+1 -> 16 | B18: Consumibles | C18: Steel Wool | D18: 0000 | E18: Pzas | F18: 7 | G18: =SUMIF('Inventario E-S'!C:C, C18, 'Inventario E-S'!D:D) - SUMIF('Inventario E-S'!C:C, C18, 'Inventario E-S'!E:E)+F18 -> 7 | I18: =I17+1 -> 8 | J18: =IF(G18<=0,"🔴 AGOTADO",IF(G18<=I18,"⚠️ BAJO","✅ OK")) -> ⚠️ BAJO
A19: =A18+1 -> 17 | B19: Consumibles | C19: Steel Wool | D19: 000 | E19: Pzas | F19: 7 | G19: =SUMIF('Inventario E-S'!C:C, C19, 'Inventario E-S'!D:D) - SUMIF('Inventario E-S'!C:C, C19, 'Inventario E-S'!E:E)+F19 -> 7 | I19: =I18+1 -> 9 | J19: =IF(G19<=0,"🔴 AGOTADO",IF(G19<=I19,"⚠️ BAJO","✅ OK")) -> ⚠️ BAJO
A20: =A19+1 -> 18 | B20: Consumibles | C20: Wood Filler | D20: Walnaut | E20: Pzas | F20: 7 | G20: =SUMIF('Inventario E-S'!C:C, C20, 'Inventario E-S'!D:D) - SUMIF('Inventario E-S'!C:C, C20, 'Inventario E-S'!E:E)+F20 -> 7 | I20: =I19+1 -> 10 | J20: =IF(G20<=0,"🔴 AGOTADO",IF(G20<=I20,"⚠️ BAJO","✅ OK")) -> ⚠️ BAJO
A21: =A20+1 -> 19 | B21: Consumibles | C21: Wood Filler | D21: White Oak | E21: Pzas | F21: 7 | G21: =SUMIF('Inventario E-S'!C:C, C21, 'Inventario E-S'!D:D) - SUMIF('Inventario E-S'!C:C, C21, 'Inventario E-S'!E:E)+F21 -> 7 | I21: =I20+1 -> 11 | J21: =IF(G21<=0,"🔴 AGOTADO",IF(G21<=I21,"⚠️ BAJO","✅ OK")) -> ⚠️ BAJO
A22: =A21+1 -> 20 | B22: Consumibles | C22: Wood Filler | D22: Alder | E22: Pzas | F22: 7 | G22: =SUMIF('Inventario E-S'!C:C, C22, 'Inventario E-S'!D:D) - SUMIF('Inventario E-S'!C:C, C22, 'Inventario E-S'!E:E)+F22 -> 7 | I22: =I21+1 -> 12 | J22: =IF(G22<=0,"🔴 AGOTADO",IF(G22<=I22,"⚠️ BAJO","✅ OK")) -> ⚠️ BAJO
A23: =A22+1 -> 21 | B23: Consumibles | C23: Wood Filler | D23: Cherry | E23: Pzas | F23: 7 | G23: =SUMIF('Inventario E-S'!C:C, C23, 'Inventario E-S'!D:D) - SUMIF('Inventario E-S'!C:C, C23, 'Inventario E-S'!E:E)+F23 -> 7 | I23: =I22+1 -> 13 | J23: =IF(G23<=0,"🔴 AGOTADO",IF(G23<=I23,"⚠️ BAJO","✅ OK")) -> ⚠️ BAJO
A24: =A23+1 -> 22 | B24: Consumibles | C24: Wood Filler | D24: Maple | E24: Pzas | F24: 7 | G24: =SUMIF('Inventario E-S'!C:C, C24, 'Inventario E-S'!D:D) - SUMIF('Inventario E-S'!C:C, C24, 'Inventario E-S'!E:E)+F24 -> 7 | I24: =I23+1 -> 14 | J24: =IF(G24<=0,"🔴 AGOTADO",IF(G24<=I24,"⚠️ BAJO","✅ OK")) -> ⚠️ BAJO
A25: =A24+1 -> 23 | B25: Consumibles | C25: Wood Filler | D25: Birch | E25: Pzas | F25: 7 | G25: =SUMIF('Inventario E-S'!C:C, C25, 'Inventario E-S'!D:D) - SUMIF('Inventario E-S'!C:C, C25, 'Inventario E-S'!E:E)+F25 -> 7 | I25: =I24+1 -> 15 | J25: =IF(G25<=0,"🔴 AGOTADO",IF(G25<=I25,"⚠️ BAJO","✅ OK")) -> ⚠️ BAJO
A26: =A25+1 -> 24 | B26: Consumibles | C26: Bondo | D26: Filler | E26: Pzas | F26: 7 | G26: =SUMIF('Inventario E-S'!C:C, C26, 'Inventario E-S'!D:D) - SUMIF('Inventario E-S'!C:C, C26, 'Inventario E-S'!E:E)+F26 -> 7 | I26: =I25+1 -> 16 | J26: =IF(G26<=0,"🔴 AGOTADO",IF(G26<=I26,"⚠️ BAJO","✅ OK")) -> ⚠️ BAJO
A27: =A26+1 -> 25 | B27: Equipo Lijero | C27: Espatulas | E27: Pzas | F27: 7 | G27: =SUMIF('Inventario E-S'!C:C, C27, 'Inventario E-S'!D:D) - SUMIF('Inventario E-S'!C:C, C27, 'Inventario E-S'!E:E)+F27 -> 7 | I27: =I26+1 -> 17 | J27: =IF(G27<=0,"🔴 AGOTADO",IF(G27<=I27,"⚠️ BAJO","✅ OK")) -> ⚠️ BAJO
A28: =A27+1 -> 26 | B28: Equipo Lijero | C28: Mascaras | D28: Anti Polvo | E28: Pzas | F28: 7 | G28: =SUMIF('Inventario E-S'!C:C, C28, 'Inventario E-S'!D:D) - SUMIF('Inventario E-S'!C:C, C28, 'Inventario E-S'!E:E)+F28 -> 7 | I28: =I27+1 -> 18 | J28: =IF(G28<=0,"🔴 AGOTADO",IF(G28<=I28,"⚠️ BAJO","✅ OK")) -> ⚠️ BAJO
A29: =A28+1 -> 27 | B29: Equipo Lijero | C29: Audifonos | D29: Prot. Auditiva | E29: Pzas | F29: 7 | G29: =SUMIF('Inventario E-S'!C:C, C29, 'Inventario E-S'!D:D) - SUMIF('Inventario E-S'!C:C, C29, 'Inventario E-S'!E:E)+F29 -> 7 | I29: =I28+1 -> 19 | J29: =IF(G29<=0,"🔴 AGOTADO",IF(G29<=I29,"⚠️ BAJO","✅ OK")) -> ⚠️ BAJO
A30: =A29+1 -> 28 | B30: Insumos | C30: Rieles | D30: 24 | E30: Cjas | F30: 7 | G30: =SUMIF('Inventario E-S'!C:C, C30, 'Inventario E-S'!D:D) - SUMIF('Inventario E-S'!C:C, C30, 'Inventario E-S'!E:E)+F30 -> 7 | I30: =I29+1 -> 20 | J30: =IF(G30<=0,"🔴 AGOTADO",IF(G30<=I30,"⚠️ BAJO","✅ OK")) -> ⚠️ BAJO
A31: =A30+1 -> 29 | B31: Insumos | C31: Rieles | D31: 21 | E31: Cjas | F31: 7 | G31: =SUMIF('Inventario E-S'!C:C, C31, 'Inventario E-S'!D:D) - SUMIF('Inventario E-S'!C:C, C31, 'Inventario E-S'!E:E)+F31 -> 7 | I31: =I30+1 -> 21 | J31: =IF(G31<=0,"🔴 AGOTADO",IF(G31<=I31,"⚠️ BAJO","✅ OK")) -> ⚠️ BAJO
A32: =A31+1 -> 30 | B32: Insumos | C32: Rieles | D32: 18 | E32: Cjas | F32: 7 | G32: =SUMIF('Inventario E-S'!C:C, C32, 'Inventario E-S'!D:D) - SUMIF('Inventario E-S'!C:C, C32, 'Inventario E-S'!E:E)+F32 -> 7 | I32: =I31+1 -> 22 | J32: =IF(G32<=0,"🔴 AGOTADO",IF(G32<=I32,"⚠️ BAJO","✅ OK")) -> ⚠️ BAJO
A33: =A32+1 -> 31 | B33: Insumos | C33: Rieles | D33: 15 | E33: Cjas | F33: 7 | G33: =SUMIF('Inventario E-S'!C:C, C33, 'Inventario E-S'!D:D) - SUMIF('Inventario E-S'!C:C, C33, 'Inventario E-S'!E:E)+F33 -> 7 | I33: 5 | J33: =IF(G33<=0,"🔴 AGOTADO",IF(G33<=I33,"⚠️ BAJO","✅ OK")) -> ✅ OK
A34: =A33+1 -> 32 | B34: Insumos | C34: Rieles | D34: 12 | E34: Cjas | F34: 7 | G34: =SUMIF('Inventario E-S'!C:C, C34, 'Inventario E-S'!D:D) - SUMIF('Inventario E-S'!C:C, C34, 'Inventario E-S'!E:E)+F34 -> 7 | I34: =I33+1 -> 6 | J34: =IF(G34<=0,"🔴 AGOTADO",IF(G34<=I34,"⚠️ BAJO","✅ OK")) -> ✅ OK
A35: =A34+1 -> 33 | B35: Insumos | C35: Clips Regulares | D35: Izquierdos | E35: Cjas | F35: 7 | G35: =SUMIF('Inventario E-S'!C:C, C35, 'Inventario E-S'!D:D) - SUMIF('Inventario E-S'!C:C, C35, 'Inventario E-S'!E:E)+F35 -> 7 | I35: =I34+1 -> 7 | J35: =IF(G35<=0,"🔴 AGOTADO",IF(G35<=I35,"⚠️ BAJO","✅ OK")) -> ⚠️ BAJO
A36: =A35+1 -> 34 | B36: Insumos | C36: Clips Regulares | D36: Derechos | E36: Cjas | F36: 7 | G36: =SUMIF('Inventario E-S'!C:C, C36, 'Inventario E-S'!D:D) - SUMIF('Inventario E-S'!C:C, C36, 'Inventario E-S'!E:E)+F36 -> 7 | I36: =I35+1 -> 8 | J36: =IF(G36<=0,"🔴 AGOTADO",IF(G36<=I36,"⚠️ BAJO","✅ OK")) -> ⚠️ BAJO
A37: =A36+1 -> 35 | B37: Insumos | C37: Visagras Normal | D37: Regulares | E37: Cjas | F37: 7 | G37: =SUMIF('Inventario E-S'!C:C, C37, 'Inventario E-S'!D:D) - SUMIF('Inventario E-S'!C:C, C37, 'Inventario E-S'!E:E)+F37 -> 7 | I37: =I36+1 -> 9 | J37: =IF(G37<=0,"🔴 AGOTADO",IF(G37<=I37,"⚠️ BAJO","✅ OK")) -> ⚠️ BAJO
A38: =A37+1 -> 36 | B38: Insumos | C38: Visagras Normal | D38: Soft Close | E38: Cjas | F38: 7 | G38: =SUMIF('Inventario E-S'!C:C, C38, 'Inventario E-S'!D:D) - SUMIF('Inventario E-S'!C:C, C38, 'Inventario E-S'!E:E)+F38 -> 7 | I38: =I37+1 -> 10 | J38: =IF(G38<=0,"🔴 AGOTADO",IF(G38<=I38,"⚠️ BAJO","✅ OK")) -> ⚠️ BAJO
A39: =A38+1 -> 37 | B39: Insumos | C39: Visagras Frame | D39: Regulares | E39: Cjas | F39: 7 | G39: =SUMIF('Inventario E-S'!C:C, C39, 'Inventario E-S'!D:D) - SUMIF('Inventario E-S'!C:C, C39, 'Inventario E-S'!E:E)+F39 -> 7 | I39: =I38+1 -> 11 | J39: =IF(G39<=0,"🔴 AGOTADO",IF(G39<=I39,"⚠️ BAJO","✅ OK")) -> ⚠️ BAJO
A40: =A39+1 -> 38 | B40: Insumos | C40: Visagras Frame | D40: Soft Close | E40: Cjas | F40: 7 | G40: =SUMIF('Inventario E-S'!C:C, C40, 'Inventario E-S'!D:D) - SUMIF('Inventario E-S'!C:C, C40, 'Inventario E-S'!E:E)+F40 -> 7 | I40: =I39+1 -> 12 | J40: =IF(G40<=0,"🔴 AGOTADO",IF(G40<=I40,"⚠️ BAJO","✅ OK")) -> ⚠️ BAJO
...

Sheet Inventario E-S
A1: INVENTARIO (ENTRADAS - SALIDAS)
A2: Fecha | B2: ID | C2: Material | D2: Entrada | E2: Salida | F2: Proyecto | G2: Proveedor | H2: Motivo (regular/urgencia/ajuste) | I2: Notas cortas
A3: 46070 | B3: =INDEX('Inventario Base'!A3:A52, MATCH(C3, 'Inventario Base'!C3:C52, 0)) -> 1 | C3: Toallas | D3: 1 | E3: 0 | F3: - | G3: Home Depot | H3: Reabastecimiento
A4: 46070 | B4: =INDEX('Inventario Base'!A4:A53, MATCH(C4, 'Inventario Base'!C4:C53, 0)) -> 4 | C4: Plasticos | D4: 5 | E4: 0 | F4: - | G4: E.B. Bradley | H4: Reabastecimiento
A5: 46070 | B5: =INDEX('Inventario Base'!A5:A54, MATCH(C5, 'Inventario Base'!C5:C54, 0)) -> 3 | C5: Papel | D5: 5 | E5: 0 | F5: - | G5: E.B. Bradley | H5: Reabastecimiento
A6: 46070 | B6: =INDEX('Inventario Base'!A6:A55, MATCH(C6, 'Inventario Base'!C6:C55, 0)) -> 4 | C6: Plasticos | D6: 5 | E6: 0 | F6: - | G6: E.B. Bradley | H6: Reabastecimiento
A7: 46070 | B7: =INDEX('Inventario Base'!A7:A56, MATCH(C7, 'Inventario Base'!C7:C56, 0)) -> 44 | C7: Straps | D7: 8 | E7: 0 | F7: - | G7: Home Depot | H7: Reabastecimiento
B8: =INDEX('Inventario Base'!A8:A57, MATCH(C8, 'Inventario Base'!C8:C57, 0)) -> #N/A
B9: =INDEX('Inventario Base'!A9:A58, MATCH(C9, 'Inventario Base'!C9:C58, 0)) -> #N/A
B10: =INDEX('Inventario Base'!A10:A59, MATCH(C10, 'Inventario Base'!C10:C59, 0)) -> #N/A
B11: =INDEX('Inventario Base'!A11:A60, MATCH(C11, 'Inventario Base'!C11:C60, 0)) -> #N/A
B12: =INDEX('Inventario Base'!A12:A61, MATCH(C12, 'Inventario Base'!C12:C61, 0)) -> #N/A
B13: =INDEX('Inventario Base'!A13:A62, MATCH(C13, 'Inventario Base'!C13:C62, 0)) -> #N/A
B14: =INDEX('Inventario Base'!A14:A63, MATCH(C14, 'Inventario Base'!C14:C63, 0)) -> #N/A
B15: =INDEX('Inventario Base'!A15:A64, MATCH(C15, 'Inventario Base'!C15:C64, 0)) -> #N/A
B16: =INDEX('Inventario Base'!A16:A65, MATCH(C16, 'Inventario Base'!C16:C65, 0)) -> #N/A
B17: =INDEX('Inventario Base'!A17:A66, MATCH(C17, 'Inventario Base'!C17:C66, 0)) -> #N/A
B18: =INDEX('Inventario Base'!A18:A67, MATCH(C18, 'Inventario Base'!C18:C67, 0)) -> #N/A
B19: =INDEX('Inventario Base'!A19:A68, MATCH(C19, 'Inventario Base'!C19:C68, 0)) -> #N/A
... B24: =INDEX('Inventario Base'!A24:A73, MATCH(C24, 'Inventario Base'!C24:C73, 0)) -> #N/A

Sheet Proveedores
A1: Proveedor | B1: Producto | C1: Contacto | D1: Teléfono | E1: Email | F1: Tiempo Entrega | G1: Precio Ref. | H1: Tipo | I1: Calificación | J1: Notas
A2: Home Depot | B2: Esmalte Blanco | C2: Juan Pérez | D2: 555-1234 | E2: ventas@comex.com | F2: 24 hrs | G2: $450/19L | I2: 4 estrellas | J2: Dan factura
A3: E.B. Bradley | B3: Laca Premium | C3: María López | D3: 555-5678 | E3: info@sherwin.com | F3: 48 hrs | G3: $800/19L | I3: 5 estrellas | J3: Mejor calidad
B4: Thinner | C4: Carlos Gómez | D4: 555-9012 | E4: berel@berel.com | F4: 24 hrs | G4: $180/20L | I4: 3 estrellas | J4: Económico

Sheet Instrucciones
A1: SISTEMA DE GESTIÓN DE PINTURA
A3: INSTRUCCIONES DE USO:
A5: 1. REGISTRO DE TRABAJOS:
A6: • Al iniciar un proyecto, registra: fecha, proyecto, color, tipo de pintura y litros estimados
A7: • Al terminar, actualiza: fecha fin y litros reales usados
A8: • La columna Diferencia se calcula automáticamente
A10: 2. INVENTARIO:
A11: • Mantén actualizada la cantidad de cada producto
A12: • La columna Estado alertará automáticamente si estás bajo el mínimo
A13: • Actualiza la fecha cada vez que uses o recibas material
A15: 3. PROVEEDORES:
A16: • Registra todos tus proveedores con información de contacto
... A26: ¡Éxito con tu sistema de gestión! 🎨
